Workbook

Sheet Klimawirkungen
A1: Stamm | E1: A. Fachliche Zerlegung (unterhalb der Klimawirkung) | N1: B. Klimarisiko ohne Anpassung | V1: C. Anpassung, Restrisiko und Handlungserfordernis
A2: ID | B2: Cluster | C2: Handlungsfeld | D2: Klimawirkung (Risiko) | E2: Bearbeitungstiefe | F2: Spezifizierung | G2: Integrierte Klimawirkungen | H2: Faktoren | I2: Indikatoren-IDs | J2: Indikatoren | K2: Typ | L2: Rein vorgelagert | M2: Systembereich | N2: Risiko o. Anp. – Gegenwart | O2: Risiko o. Anp. – Mitte optim. | P2: Risiko o. Anp. – Mitte pessim. | Q2: Risiko o. Anp. – Ende optim. | R2: Risiko o. Anp. – Ende pessim. | S2: Gewissheit – Mitte | T2: Gewissheit – Ende | U2: Anpassungsdauer (Jahre) | V2: Anpassungskapazität analysiert | W2: Wirksamkeit APA III – 2020–2030 | X2: Wirksamkeit APA III – Mitte optim. | Y2: Wirksamkeit APA III – Mitte pessim. | Z2: Wirksamkeit weiterr. – Mitte optim. | AA2: Wirksamkeit weiterr. – Mitte pessim. | AB2: Restrisiko APA III – 2020–2030 | AC2: Restrisiko APA III – Mitte optim. | AD2: Restrisiko APA III – Mitte pessim. | AE2: Restrisiko weiterr. – Mitte optim. | AF2: Restrisiko weiterr. – Mitte pessim. | AG2: Handlungserfordernis | AH2: Netzrolle (TB 6 Kap. 3.4) | AI2: Grenzen der Anpassung | AJ2: Quelle | AK2: Anmerkung
A3: 1 | B3: Land | C3: Biologische Vielfalt | D3: Veränderung der Länge der Vegetationsperiode und Phänologie | E3: intensiv | F3: Veränderungen im Verhalten von Zugvögeln und Entkopplungsphänomene infolge von Verschiebungen des Vorkommens von Nahrungsinsekten | G3: „Phänologie“, „Länge der Vegetationsperiode“, „Phänologie und Verhalten“ | K3: Risiko | M3: Natürliche Systeme und Ressourcen | N3: gering | O3: mittel | P3: hoch | Q3: mittel | R3: hoch | S3: mittel | T3: gering | U3: keine Reaktion möglich | V3: nein | AG3: nicht zuordenbar (keine Anpassungsoption) | AH3: stark ausgehend | AI3: Klimarisiko hoch, aber keine Anpassungsmöglichkeit gesehen (TB6 Kap. 6.1) | AJ3: TB 6 Tab. 1 | TB 2–5 „Übersicht Klimawirkungen“
A4: 2 | B4: Land | C4: Biologische Vielfalt | D4: Ausbreitung invasiver Arten | E4: intensiv | K4: Risiko | M4: Natürliche Systeme und Ressourcen | N4: mittel | O4: mittel | P4: hoch | Q4: hoch | R4: hoch | S4: mittel | T4: gering | U4: 10-50 | V4: ja | W4: gering | X4: gering-mittel | Y4: gering | Z4: mittel | AA4: gering-mittel | AB4: mittel | AC4: gering-mittel | AD4: hoch | AE4: gering | AF4: mittel-hoch | AG4: sehr dringend | AJ4: TB 6 Tab. 1 | TB 6 Tab. 22 | TB 2–5 „Klimarisiken mit Anpassung“ | TB 2–5 „Übersicht Klimawirkungen“
A5: 3 | B5: Land | C5: Biologische Vielfalt | D5: Verlust an genetischer Vielfalt | E5: extensiv | K5: Risiko | M5: Natürliche Systeme und Ressourcen | N5: gering | O5: gering | P5: mittel | Q5: mittel | R5: hoch | S5: mittel | T5: sehr gering | U5: 10-50 | V5: ja | W5: gering | X5: gering | Y5: gering | Z5: gering-mittel | AA5: gering-mittel | AB5: gering | AC5: gering | AD5: mittel | AE5: gering | AF5: gering-mittel | AG5: dringend | AJ5: TB 6 Tab. 1 | TB 6 Tab. 22 | TB 2–5 „Klimarisiken mit Anpassung“ | TB 2–5 „Übersicht Klimawirkungen“
A6: 4 | B6: Land | C6: Biologische Vielfalt | D6: Verschiebung von Arealen und Rückgang der Bestände | E6: extensiv | G6: „Rückgang der Bestände“ | K6: Risiko | M6: Natürliche Systeme und Ressourcen | N6: gering | O6: mittel | P6: mittel | Q6: mittel | R6: hoch | S6: mittel | T6: gering | U6: 10-50 | V6: ja | W6: gering | X6: gering-mittel | Y6: gering | Z6: mittel | AA6: gering-mittel | AB6: gering | AC6: gering-mittel | AD6: mittel | AE6: gering | AF6: gering-mittel | AG6: dringend | AH6: stark ausgehend | AJ6: TB 6 Tab. 1 | TB 6 Tab. 22 | TB 2–5 „Klimarisiken mit Anpassung“ | TB 2–5 „Übersicht Klimawirkungen“
A7: 5 | B7: Land | C7: Biologische Vielfalt | D7: Schäden an Küstenökosystemen | E7: extensiv | K7: Risiko | M7: Natürliche Systeme und Ressourcen | N7: gering | O7: mittel | P7: mittel | Q7: mittel | R7: hoch | S7: mittel | T7: mittel | U7: 10-50 | V7: nein | AG7: dringend | AH7: stark eingehend | AJ7: TB 6 Tab. 1 | TB 2–5 „Übersicht Klimawirkungen“
A8: 6 | B8: Land | C8: Biologische Vielfalt | D8: Schäden an Gebirgsökosystemen | E8: extensiv | K8: Risiko | M8: Natürliche Systeme und Ressourcen | N8: gering | O8: mittel | P8: hoch | Q8: mittel | R8: hoch | S8: mittel | T8: mittel | U8: keine Reaktion möglich | V8: nein | AG8: nicht zuordenbar (keine Anpassungsoption) | AI8: Klimarisiko hoch, aber keine Anpassungsmöglichkeit gesehen (TB6 Kap. 6.1) | AJ8: TB 6 Tab. 1 | TB 2–5 „Übersicht Klimawirkungen“
A9: 7 | B9: Land | C9: Biologische Vielfalt | D9: Schäden an wassergebundenen Habitaten und Feuchtgebieten | E9: extensiv | K9: Risiko | M9: Natürliche Systeme und Ressourcen | N9: mittel | O9: mittel | P9: hoch | Q9: mittel | R9: hoch | S9: mittel | T9: mittel | U9: 10-50 | V9: ja | W9: gering | X9: gering-mittel | Y9: gering-mittel | Z9: mittel | AA9: mittel | AB9: mittel | AC9: gering-mittel | AD9: mittel-hoch | AE9: gering | AF9: mittel | AG9: sehr dringend | AJ9: TB 6 Tab. 1 | TB 6 Tab. 22 | TB 2–5 „Klimarisiken mit Anpassung“ | TB 2–5 „Übersicht Klimawirkungen“
A10: 8 | B10: Land | C10: Biologische Vielfalt | D10: Schäden an Wäldern | E10: extensiv | K10: Risiko | M10: Natürliche Systeme und Ressourcen | N10: mittel | O10: mittel | P10: hoch | Q10: mittel | R10: hoch | S10: mittel | T10: gering | U10: > 50 | V10: ja | W10: gering | X10: gering-mittel | Y10: gering-mittel | Z10: mittel | AA10: gering-mittel | AB10: mittel | AC10: gering-mittel | AD10: mittel-hoch | AE10: gering | AF10: mittel-hoch | AG10: sehr dringend | AJ10: TB 6 Tab. 1 | TB 6 Tab. 22 | TB 2–5 „Klimarisiken mit Anpassung“ | TB 2–5 „Übersicht Klimawirkungen“
A11: 9 | B11: Land | C11: Biologische Vielfalt | D11: Ökosystemleistungen | E11: extensiv | G11: „Versorgungsleistungen“, „Regulierende Leistungen“ | K11: Risiko | M11: Naturnutzende Wirtschaftssysteme | N11: gering | O11: gering | P11: mittel | Q11: mittel | R11: hoch | S11: sehr gering | T11: sehr gering | U11: 10-50 | V11: nein | AG11: dringend | AJ11: TB 6 Tab. 1 | TB 2–5 „Übersicht Klimawirkungen“
A12: 10 | B12: Land | C12: Boden | D12: Bodenerosion durch Wasser | E12: intensiv | F12: Potenzieller mittlerer Bodenabtrag durch Wassererosion | H12: Erosion durch Wasser | I12: BO-KL-01 | J12: BO-KL-01: Potenzieller mittlerer Bodenabtrag durch Wassererosion | K12: Risiko | M12: Natürliche Systeme und Ressourcen | N12: mittel | O12: mittel | P12: hoch | Q12: mittel | R12: hoch | S12: mittel | T12: gering | U12: 10-50 | V12: ja | W12: gering | X12: gering-mittel | Y12: gering-mittel | Z12: mittel | AA12: mittel | AB12: mittel | AC12: gering-mittel | AD12: mittel-hoch | AE12: gering | AF12: mittel-hoch | AG12: sehr dringend | AJ12: TB 6 Tab. 1 | TB 6 Tab. 22 | TB 2–5 „Klimarisiken mit Anpassung“ | TB 2–5 „Übersicht Klimawirkungen“
A13: 11 | B13: Land | C13: Boden | D13: Bodenerosion durch Wind | E13: extensiv | K13: Risiko | M13: Natürliche Systeme und Ressourcen | N13: mittel | O13: mittel | P13: hoch | Q13: mittel | R13: hoch | S13: mittel | T13: gering | U13: 10-50 | V13: ja | W13: gering | X13: gering | Y13: gering | Z13: mittel | AA13: mittel | AB13: mittel | AC13: mittel | AD13: hoch | AE13: gering | AF13: mittel | AG13: sehr dringend | AJ13: TB 6 Tab. 1 | TB 6 Tab. 22 | TB 2–5 „Klimarisiken mit Anpassung“ | TB 2–5 „Übersicht Klimawirkungen“
A14: 12 | B14: Land | C14: Boden | D14: Rutschungen und Muren | E14: extensiv | K14: Risiko | M14: Natürliche Systeme und Ressourcen | N14: gering | O14: gering | P14: mittel | Q14: gering | R14: mittel | S14: gering | T14: gering | U14: 10-50 | V14: nein | AG14: dringend | AH14: stark ausgehend | AJ14: TB 6 Tab. 1 | TB 2–5 „Übersicht Klimawirkungen“
A15: 13 | B15: Land | C15: Boden | D15: Wassermangel im Boden | E15: intensiv | H15: Wassermangel im Boden | I15: BO-KL-02 | J15: BO-KL-02: Effektive Wasserbilanz [mm] während der Hauptvegetationsperiode | K15: Risiko | M15: Natürliche Systeme und Ressourcen | N15: mittel | O15: mittel | P15: hoch | Q15: mittel | R15: hoch | S15: gering | T15: gering | U15: 10-50 | V15: ja | W15: gering | X15: gering-mittel | Y15: gering-mittel | Z15: mittel | AA15: mittel | AB15: mittel | AC15: gering-mittel | AD15: mittel-hoch | AE15: gering | AF15: mittel | AG15: sehr dringend | AH15: stark ausgehend | AJ15: TB 6 Tab. 1 | TB 6 Tab. 22 | TB 2–5 „Klimarisiken mit Anpassung“ | TB 2–5 „Übersicht Klimawirkungen“
A16: 14 | B16: Land | C16: Boden | D16: Sickerwasser | E16: intensiv | H16: Sickerwasser | I16: BO-KL-03 | J16: BO-KL-03: Mittlere jährliche Sickerwasserrate [mm/a] | K16: Risiko | L16: ja | M16: Natürliche Systeme und Ressourcen | N16: mittel | O16: mittel | P16: hoch | Q16: mittel | R16: hoch | S16: gering | T16: gering | U16: keine Reaktion möglich | V16: nein | AG16: nicht als (sehr) dringend ausgewiesen | AH16: stark ausgehend | AJ16: TB 6 Tab. 1 | TB 2–5 „Übersicht Klimawirkungen“
A17: 15 | B17: Land | C17: Boden | D17: Vernässung | E17: intensiv | H17: Vernässung | I17: BO-KL-04 | J17: BO-KL-04: Anzahl der Tage mit Bodenfeuchte ≥ 100 Prozent nutzbare Feldkapazität | K17: Risiko | L17: ja | M17: Natürliche Systeme und Ressourcen | N17: gering | O17: gering | P17: mittel | Q17: gering | R17: mittel | S17: gering | T17: gering | U17: keine Reaktion möglich | V17: nein | AG17: nicht als (sehr) dringend ausgewiesen | AH17: stark ausgehend | AJ17: TB 6 Tab. 1 | TB 2–5 „Übersicht Klimawirkungen“
A18: 16 | B18: Land | C18: Boden | D18: Bodenbiologie: Mikrobiologische Aktivität / Biodiversität / biologische Funktionalität | E18: extensiv | K18: Risiko | M18: Natürliche Systeme und Ressourcen | N18: gering | O18: gering | P18: mittel | Q18: gering | R18: mittel | S18: sehr gering | T18: sehr gering | U18: keine Reaktion möglich | V18: nein | AG18: nicht zuordenbar (keine Anpassungsoption) | AI18: Klimarisiko mittel, aber keine Anpassungsmöglichkeit gesehen (TB6 Kap. 6.1) | AJ18: TB 6 Tab. 1 | TB 2–5 „Übersicht Klimawirkungen“
A19: 17 | B19: Land | C19: Boden | D19: Bodenstoffhaushalt: Organische Bodensubstanz, Stickstoff- und Phosphorhaushalt, Stoffausträge | E19: extensiv | K19: Risiko | M19: Natürliche Systeme und Ressourcen | N19: gering | O19: gering | P19: mittel | Q19: gering | R19: mittel | S19: gering | T19: gering | U19: < 10 | V19: nein | AG19: nicht als (sehr) dringend ausgewiesen | AJ19: TB 6 Tab. 1 | TB 2–5 „Übersicht Klimawirkungen“
A20: 18 | B20: Land | C20: Boden | D20: Bodenfunktionen: Filter- und Pufferfunktionen | E20: extensiv | K20: Risiko | M20: Natürliche Systeme und Ressourcen | N20: gering | O20: gering | P20: gering | Q20: gering | R20: mittel | S20: gering | T20: gering | U20: keine Reaktion möglich | V20: nein | AG20: nicht zuordenbar (keine Anpassungsoption) | AI20: Klimarisiko mittel, aber keine Anpassungsmöglichkeit gesehen (TB6 Kap. 6.1) | AJ20: TB 6 Tab. 1 | TB 2–5 „Übersicht Klimawirkungen“
A21: 19 | B21: Land | C21: Boden | D21: Produktionsfunktionen | E21: extensiv | K21: Risiko | M21: Naturnutzende Wirtschaftssysteme | N21: mittel | O21: mittel | P21: hoch | Q21: mittel | R21: hoch | S21: gering | T21: gering | U21: 10-50 | V21: ja | W21: gering | X21: gering-mittel | Y21: gering-mittel | Z21: mittel | AA21: gering-mittel | AB21: mittel | AC21: gering-mittel | AD21: mittel-hoch | AE21: gering | AF21: mittel-hoch | AG21: sehr dringend | AJ21: TB 6 Tab. 1 | TB 6 Tab. 22 | TB 2–5 „Klimarisiken mit Anpassung“ | TB 2–5 „Übersicht Klimawirkungen“
A22: 20 | B22: Land | C22: Landwirtschaft | D22: Hitzestress bei und Leistung von Nutztieren | E22: intensiv | F22: Hitzestress bei Milchkühen | H22: Lufttemperatur, Luftfeuchte | I22: LW-KL-01, LW-KL-02, LW-KL-03 | J22: LW-KL-01: Anzahl der Tage mit einem THI > 60 bis 70 · LW-KL-02: Anzahl der Tage mit einem THI > 70 bis 80 · LW-KL-03: Anzahl der Tage mit einem THI > 80 | K22: Risiko | M22: Naturnutzende Wirtschaftssysteme | N22: gering | O22: gering | P22: mittel | Q22: mittel | R22: hoch | S22: mittel | T22: mittel | U22: < 10 | V22: nein | AG22: nicht als (sehr) dringend ausgewiesen | AJ22: TB 6 Tab. 1 | TB 2–5 „Übersicht Klimawirkungen“
A23: 21 | B23: Land | C23: Landwirtschaft | D23: Abiotischer Stress (Pflanzen) | E23: intensiv | F23: Trocken- und Hitzestress beim Weizen | H23: Trockenheit · Hitze | I23: LW-KL-04, LW-KL-05, LW-KL-06, LW-KL-07, LW-KL-08, LW-KL-09, LW-KL-10 | J23: LW-KL-04: Tage mit Bodenfeuchte < 30 % nFK, 01.09.–30.11., Winterweizen · LW-KL-05: Tage mit Bodenfeuchte < 30 % nFK, 01.03.–30.06., Winterweizen · LW-KL-06: Tage mit Bodenfeuchte < 50 % nFK, 01.09.–30.11., Winterweizen · LW-KL-07: Tage mit Bodenfeuchte < 50 % nFK, 01.03.–30.06., Winterweizen · LW-KL-08: Mittlere Bodenfeuchte 01.09.–30.11., Winterweizen · LW-KL-09: Mittlere Bodenfeuchte 01.03.–30.06., Winterweizen · LW-KL-10: Anzahl der Heißen Tage in den Monaten Mai und Juni | K23: Risiko | M23: Naturnutzende Wirtschaftssysteme | N23: mittel | O23: mittel | P23: hoch | Q23: mittel | R23: hoch | S23: mittel | T23: mittel | U23: 10-50 | V23: ja | W23: gering | X23: gering | Y23: gering | Z23: mittel-hoch | AA23: mittel | AB23: mittel | AC23: mittel | AD23: hoch | AE23: gering | AF23: mittel | AG23: sehr dringend | AJ23: TB 6 Tab. 1 | TB 6 Tab. 22 | TB 2–5 „Klimarisiken mit Anpassung“ | TB 2–5 „Übersicht Klimawirkungen“
A24: 22 | B24: Land | C24: Landwirtschaft | D24: Verschiebung von Anbaugebieten | E24: extensiv | K24: Risiko | M24: Naturnutzende Wirtschaftssysteme | N24: gering | O24: gering | P24: mittel | Q24: mittel | R24: mittel | S24: hoch | T24: mittel | U24: < 10 | V24: nein | AG24: nicht als (sehr) dringend ausgewiesen | AJ24: TB 6 Tab. 1 | TB 2–5 „Übersicht Klimawirkungen“
A25: 23 | B25: Land | C25: Landwirtschaft | D25: Agrophänologische Phasen und Wachstumsperiode | E25: extensiv | K25: Risiko | M25: Naturnutzende Wirtschaftssysteme | N25: gering | O25: gering | P25: mittel | Q25: mittel | R25: mittel | S25: hoch | T25: mittel | U25: < 10 | V25: nein | AG25: nicht als (sehr) dringend ausgewiesen | AJ25: TB 6 Tab. 1 | TB 2–5 „Übersicht Klimawirkungen“
A26: 24 | B26: Land | C26: Landwirtschaft | D26: Stress durch Schädlinge und Krankheiten (Pflanzen) | E26: extensiv | K26: Risiko | M26: Naturnutzende Wirtschaftssysteme | N26: gering | O26: gering | P26: mittel | Q26: gering | R26: mittel | S26: mittel | T26: gering | U26: < 10 | V26: nein | AG26: nicht als (sehr) dringend ausgewiesen | AJ26: TB 6 Tab. 1 | TB 2–5 „Übersicht Klimawirkungen“
A27: 25 | B27: Land | C27: Landwirtschaft | D27: Ertragsausfälle | E27: extensiv | K27: Risiko | M27: Naturnutzende Wirtschaftssysteme | N27: mittel | O27: mittel | P27: hoch | Q27: mittel | R27: hoch | S27: gering | T27: gering | U27: 10-50 | V27: ja | W27: gering | X27: gering-mittel | Y27: gering-mittel | Z27: mittel-hoch | AA27: mittel | AB27: mittel | AC27: gering-mittel | AD27: mittel-hoch | AE27: gering | AF27: mittel | AG27: sehr dringend | AH27: stark eingehend | AJ27: TB 6 Tab. 1 | TB 6 Tab. 22 | TB 2–5 „Klimarisiken mit Anpassung“ | TB 2–5 „Übersicht Klimawirkungen“
A28: 26 | B28: Land | C28: Landwirtschaft | D28: Qualität der Ernteprodukte | E28: extensiv | K28: Risiko | M28: Naturnutzende Wirtschaftssysteme | N28: gering | O28: gering | P28: mittel | Q28: gering | R28: mittel | S28: hoch | T28: mittel | U28: < 10 | V28: nein | AG28: nicht als (sehr) dringend ausgewiesen | AH28: stark eingehend | AJ28: TB 6 Tab. 1 | TB 2–5 „Übersicht Klimawirkungen“
A29: 27 | B29: Land | C29: Wald- und Forstwirtschaft | D29: Hitze- und Trockenstress | E29: intensiv | F29: Trockenstress bei Buche, Eiche, Fichte und Kiefer | H29: Trockenheit (klimatische Wasserbilanz) | I29: FW-KL-01 | J29: FW-KL-01: Ökogramme für Buche, Eiche, Fichte und Kiefer | K29: Risiko | M29: Naturnutzende Wirtschaftssysteme | N29: mittel | O29: mittel | P29: hoch | Q29: mittel | R29: hoch | S29: mittel | T29: mittel | U29: > 50 | V29: ja | W29: gering | X29: mittel | Y29: gering-mittel | Z29: mittel | AA29: gering-mittel | AB29: mittel | AC29: gering | AD29: mittel-hoch | AE29: gering | AF29: mittel-hoch | AG29: sehr dringend | AJ29: TB 6 Tab. 1 | TB 6 Tab. 22 | TB 2–5 „Klimarisiken mit Anpassung“ | TB 2–5 „Übersicht Klimawirkungen“
A30: 28 | B30: Land | C30: Wald- und Forstwirtschaft | D30: Stress durch Schädlinge / Krankheiten | E30: intensiv | F30: Potenzielle Anzahl der Vermehrungszyklen des Buchdruckers (Ips typographus) | H30: Schädlingsdruck · Verbreitung der betroffenen Baumart | I30: FW-KL-02, FW-SO-03 | J30: FW-KL-02: Potenzielle Anzahl der Vermehrungszyklen des Buchdruckers (Ips typographus) · FW-SO-03: Flächenanteil der Baumgattung Picea (Fichte) am bestockten Holzboden | K30: Risiko | M30: Naturnutzende Wirtschaftssysteme | N30: mittel | O30: mittel | P30: hoch | Q30: mittel | R30: hoch | S30: mittel | T30: gering | U30: > 50 | V30: ja | W30: gering | X30: gering-mittel | Y30: gering-mittel | Z30: mittel | AA30: gering-mittel | AB30: mittel | AC30: gering-mittel | AD30: mittel-hoch | AE30: gering | AF30: mittel-hoch | AG30: sehr dringend | AJ30: TB 6 Tab. 1 | TB 6 Tab. 22 | TB 2–5 „Klimarisiken mit Anpassung“ | TB 2–5 „Übersicht Klimawirkungen“
A31: 29 | B31: Land | C31: Wald- und Forstwirtschaft | D31: Schäden durch Windwurf | E31: extensiv | K31: Risiko | M31: Naturnutzende Wirtschaftssysteme | N31: mittel | O31: mittel | P31: mittel | Q31: mittel | R31: mittel | S31: mittel | T31: gering | U31: > 50 | V31: nein | AG31: dringend | AJ31: TB 6 Tab. 1 | TB 2–5 „Übersicht Klimawirkungen“
A32: 30 | B32: Land | C32: Wald- und Forstwirtschaft | D32: Waldbrandrisiko | E32: extensiv | K32: Risiko | M32: Naturnutzende Wirtschaftssysteme | N32: gering | O32: gering | P32: mittel | Q32: mittel | R32: hoch | S32: mittel | T32: gering | U32: > 50 | V32: ja | W32: gering-mittel | X32: gering-mittel | Y32: gering | Z32: mittel | AA32: gering-mittel | AB32: gering | AC32: gering | AD32: mittel | AE32: gering | AF32: gering-mittel | AG32: sehr dringend | AJ32: TB 6 Tab. 1 | TB 6 Tab. 22 | TB 2–5 „Klimarisiken mit Anpassung“ | TB 2–5 „Übersicht Klimawirkungen“
A33: 31 | B33: Land | C33: Wald- und Forstwirtschaft | D33: Nutzfunktion: Holzertrag | E33: extensiv | K33: Risiko | M33: Naturnutzende Wirtschaftssysteme | N33: mittel | O33: mittel | P33: hoch | Q33: mittel | R33: hoch | S33: mittel | T33: gering | U33: 10-50 | V33: ja | W33: gering | X33: mittel | Y33: gering-mittel | Z33: mittel | AA33: gering-mittel | AB33: mittel | AC33: gering | AD33: mittel-hoch | AE33: gering | AF33: mittel-hoch | AG33: sehr dringend | AH33: stark eingehend | AJ33: TB 6 Tab. 1 | TB 6 Tab. 22 | TB 2–5 „Klimarisiken mit Anpassung“ | TB 2–5 „Übersicht Klimawirkungen“
A34: 32 | B34: Land | C34: Wald- und Forstwirtschaft | D34: Nutzfunktion: Erholung | E34: extensiv | K34: Risiko | M34: Naturnutzende Wirtschaftssysteme | N34: gering | O34: gering | P34: mittel | Q34: gering | R34: mittel | S34: mittel | T34: gering | U34: > 50 | V34: nein | AG34: dringend | AJ34: TB 6 Tab. 1 | TB 2–5 „Übersicht Klimawirkungen“
A35: 33 | B35: Wasser | C35: Fischerei | D35: Entkopplung von Nahrungsbeziehungen in der Ostsee | E35: intensiv | F35: Am Beispiel des Herings; Raumbezug westliche Ostsee; Ansatz Produktivität; Fokus Phänologie | K35: Risiko | M35: Naturnutzende Wirtschaftssysteme | N35: mittel | O35: hoch | P35: hoch | Q35: mittel | R35: hoch | S35: hoch | T35: sehr gering | U35: < 10 | V35: ja | W35: gering | X35: gering | Y35: gering | Z35: mittel | AA35: gering-mittel | AB35: mittel | AC35: hoch | AD35: hoch | AE35: mittel | AF35: mittel-hoch | AG35: dringend | AJ35: TB 6 Tab. 1 | TB 6 Tab. 22 | TB 2–5 „Klimarisiken mit Anpassung“ | TB 2–5 „Übersicht Klimawirkungen“
A36: 34 | B36: Wasser | C36: Fischerei | D36: Verbreitung wärmeliebender Arten in der Nordsee | E36: intensiv | F36: Am Beispiel des Seehechts; Raumbezug mittlere Nordsee; Ansatz Habitat/Vorkommen; Fokus Physiologie | H36: Verbreitung des Seehechts in der Deutschen Bucht | I36: FI-KL-01 | J36: FI-KL-01: Relative Habitateignung der Deutschen Bucht | K36: Risiko | M36: Naturnutzende Wirtschaftssysteme | N36: gering | O36: mittel | P36: mittel | Q36: mittel | R36: mittel | S36: mittel | T36: gering | U36: < 10 | V36: nein | AG36: nicht als (sehr) dringend ausgewiesen | AJ36: TB 6 Tab. 1 | TB 2–5 „Übersicht Klimawirkungen“
A37: 35 | B37: Wasser | C37: Fischerei | D37: Verbreitung von Fischarten in Fließgewässern | E37: intensiv | F37: Am Beispiel von Bachforelle, Brachse, Groppe und Strömer in Baden-Württemberg | H37: Potenzielle Verbreitung von Bachforelle, Brachse, Groppe und Strömer | I37: FI-KL-02 | J37: FI-KL-02: Habitateignung der Fließgewässer Baden-Württembergs | K37: Risiko | M37: Naturnutzende Wirtschaftssysteme | N37: gering | O37: mittel | P37: hoch | Q37: mittel | R37: hoch | S37: hoch | T37: gering | U37: 10-50 | V37: ja | W37: gering-mittel | X37: gering-mittel | Y37: gering-mittel | Z37: mittel | AA37: gering-mittel | AB37: gering | AC37: gering-mittel | AD37: mittel-hoch | AE37: gering | AF37: mittel-hoch | AG37: sehr dringend | AJ37: TB 6 Tab. 1 | TB 6 Tab. 22 | TB 2–5 „Klimarisiken mit Anpassung“ | TB 2–5 „Übersicht Klimawirkungen“
A38: 36 | B38: Wasser | C38: Fischerei | D38: Stress durch Schädlinge / Krankheiten | E38: extensiv | K38: Risiko | M38: Naturnutzende Wirtschaftssysteme | N38: gering | O38: gering | P38: mittel | Q38: mittel | R38: hoch | S38: mittel | T38: sehr gering | U38: < 10 | V38: nein | AG38: nicht als (sehr) dringend ausgewiesen | AJ38: TB 6 Tab. 1 | TB 2–5 „Übersicht Klimawirkungen“
A39: 37 | B39: Wasser | C39: Fischerei | D39: Schäden an Aquakulturen | E39: extensiv | K39: Risiko | M39: Naturnutzende Wirtschaftssysteme | N39: gering | O39: gering | P39: mittel | Q39: mittel | R39: mittel | S39: mittel | T39: gering | U39: < 10 | V39: nein | AG39: nicht als (sehr) dringend ausgewiesen | AJ39: TB 6 Tab. 1 | TB 2–5 „Übersicht Klimawirkungen“
A40: 38 | B40: Wasser | C40: Küsten- und Meeresschutz | D40: Meerestemperatur und Eisbedeckung | E40: intensiv | H40: Meerestemperatur | I40: KUE-KL-01 | J40: KUE-KL-01: Meerestemperatur in der Deutschen Bucht und der südwestlichen Ostsee | K40: Risiko | L40: ja | M40: Natürliche Systeme und Ressourcen | N40: mittel | O40: hoch | P40: hoch | Q40: hoch | R40: hoch | S40: hoch | T40: hoch | U40: > 50 | V40: nein | AG40: nicht als (sehr) dringend ausgewiesen | AH40: stark ausgehend | AJ40: TB 6 Tab. 1 | TB 2–5 „Übersicht Klimawirkungen“
...

Sheet Handlungsfelder
A1: Klimarisiken auf Ebene der 13 Handlungsfelder
A2: Quelle: Teilberichte 2–5, jeweils Tabelle „Klimarisiken mit Anpassung im Handlungsfeld …“. Fünfstufige Skala.
A4: Cluster | B4: Handlungsfeld | C4: Klimawirkungen | D4: ohne Anp. – Gegenwart | E4: ohne Anp. – Mitte optim. | F4: ohne Anp. – Mitte pessim. | G4: APA III – 2020–2030 | H4: APA III – Mitte optim. | I4: APA III – Mitte pessim. | J4: weiterr. – Mitte optim. | K4: weiterr. – Mitte pessim.
A5: Land | B5: Biologische Vielfalt | C5: 9 | D5: gering | E5: mittel | F5: mittel-hoch | G5: gering | H5: gering-mittel | I5: mittel-hoch | J5: gering | K5: mittel
A6: Land | B6: Boden | C6: 10 | D6: gering-mittel | E6: gering-mittel | F6: mittel-hoch | G6: gering-mittel | H6: gering | I6: mittel | J6: gering | K6: gering-mittel
A7: Land | B7: Landwirtschaft | C7: 7 | D7: mittel | E7: mittel | F7: hoch | G7: mittel | H7: gering-mittel | I7: hoch | J7: gering | K7: mittel
A8: Land | B8: Wald- und Forstwirtschaft | C8: 6 | D8: mittel | E8: mittel | F8: hoch | G8: mittel | H8: gering-mittel | I8: hoch | J8: gering | K8: mittel-hoch
A9: Wasser | B9: Fischerei | C9: 5 | D9: gering-mittel | E9: mittel | F9: hoch | G9: gering-mittel | H9: gering-mittel | I9: mittel-hoch | J9: gering | K9: mittel-hoch
A10: Wasser | B10: Küsten- und Meeresschutz | C10: 10 | D10: mittel | E10: mittel | F10: hoch | G10: gering-mittel | H10: gering-mittel | I10: mittel-hoch | J10: gering | K10: mittel
A11: Wasser | B11: Wasserhaushalt, Wasserwirtschaft | C11: 11 | D11: mittel | E11: mittel | F11: hoch | G11: gering-mittel | H11: gering-mittel | I11: mittel-hoch | J11: gering | K11: mittel
A12: Infrastruktur | B12: Bauwesen | C12: 6 | D12: mittel | E12: mittel | F12: mittel-hoch | G12: gering-mittel | H12: gering-mittel | I12: mittel | J12: gering | K12: gering-mittel
A13: Infrastruktur | B13: Energiewirtschaft | C13: 6 | D13: gering | E13: gering | F13: gering | G13: gering | H13: gering | I13: gering | J13: gering | K13: gering
A14: Infrastruktur | B14: Verkehr, Verkehrsinfrastruktur | C14: 7 | D14: gering-mittel | E14: gering | F14: mittel | G14: gering | H14: gering | I14: gering-mittel | J14: gering | K14: gering
A15: Wirtschaft | B15: Industrie und Gewerbe | C15: 12 | D15: mittel | E15: gering | F15: mittel | G15: gering-mittel | H15: gering | I15: mittel | J15: gering | K15: gering
A16: Wirtschaft | B16: Tourismuswirtschaft | C16: 5 | D16: gering | E16: gering | F16: mittel | G16: gering | H16: gering | I16: mittel | J16: gering | K16: gering-mittel
A17: Gesundheit | B17: Menschliche Gesundheit | C17: 8 | D17: mittel | E17: mittel | F17: hoch | G17: gering-mittel | H17: gering | I17: mittel | J17: gering | K17: mittel
B18: Summe | C18: =SUM(C5:C17) -> 102

Sheet Indikatoren
A1: Indikatoren der quantitativen Operationalisierung
A2: Quelle: Teilberichte 2–5, Tabellen „Übersicht über Faktoren und Indikatoren …“. Kennblätter zu jedem Indikator stehen im Anhang der KWRA (Climate Change 20/2021).
A4: Klimawirkung-ID | B4: Handlungsfeld | C4: Klimawirkung | D4: Indikatoren-ID | E4: Faktor | F4: Indikator
A5: 10 | B5: Boden | C5: Bodenerosion durch Wasser | D5: BO-KL-01 | E5: Erosion durch Wasser | F5: Potenzieller mittlerer Bodenabtrag durch Wassererosion
A6: 13 | B6: Boden | C6: Wassermangel im Boden | D6: BO-KL-02 | E6: Wassermangel im Boden | F6: Effektive Wasserbilanz [mm] während der Hauptvegetationsperiode
A7: 14 | B7: Boden | C7: Sickerwasser | D7: BO-KL-03 | E7: Sickerwasser | F7: Mittlere jährliche Sickerwasserrate [mm/a]
A8: 15 | B8: Boden | C8: Vernässung | D8: BO-KL-04 | E8: Vernässung | F8: Anzahl der Tage mit Bodenfeuchte ≥ 100 Prozent nutzbare Feldkapazität
A9: 20 | B9: Landwirtschaft | C9: Hitzestress bei und Leistung von Nutztieren | D9: LW-KL-01 | E9: Lufttemperatur, Luftfeuchte | F9: Anzahl der Tage mit einem THI > 60 bis 70
A10: 20 | B10: Landwirtschaft | C10: Hitzestress bei und Leistung von Nutztieren | D10: LW-KL-02 | E10: Lufttemperatur, Luftfeuchte | F10: Anzahl der Tage mit einem THI > 70 bis 80
A11: 20 | B11: Landwirtschaft | C11: Hitzestress bei und Leistung von Nutztieren | D11: LW-KL-03 | E11: Lufttemperatur, Luftfeuchte | F11: Anzahl der Tage mit einem THI > 80
A12: 21 | B12: Landwirtschaft | C12: Abiotischer Stress (Pflanzen) | D12: LW-KL-04 | E12: Trockenheit | F12: Tage mit Bodenfeuchte < 30 % nFK, 01.09.–30.11., Winterweizen
A13: 21 | B13: Landwirtschaft | C13: Abiotischer Stress (Pflanzen) | D13: LW-KL-05 | E13: Trockenheit | F13: Tage mit Bodenfeuchte < 30 % nFK, 01.03.–30.06., Winterweizen
A14: 21 | B14: Landwirtschaft | C14: Abiotischer Stress (Pflanzen) | D14: LW-KL-06 | E14: Trockenheit | F14: Tage mit Bodenfeuchte < 50 % nFK, 01.09.–30.11., Winterweizen
A15: 21 | B15: Landwirtschaft | C15: Abiotischer Stress (Pflanzen) | D15: LW-KL-07 | E15: Trockenheit | F15: Tage mit Bodenfeuchte < 50 % nFK, 01.03.–30.06., Winterweizen
A16: 21 | B16: Landwirtschaft | C16: Abiotischer Stress (Pflanzen) | D16: LW-KL-08 | E16: Trockenheit | F16: Mittlere Bodenfeuchte 01.09.–30.11., Winterweizen
... A71: 97 | B71: Menschliche Gesundheit | C71: Potenziell schädliche Mikroorganismen und Algen | D71: GE-KL-08 | E71: Wassertemperatur an der Ostseeküste | F71: Tag im Jahr, an dem das Oberflächenwasser erstmals den Schwellenwert überschreitet

Sheet Wirkungsmechanismen
A1: Wirkungsmechanismen je Klimawirkung — Hazard / Vulnerabilität / Exposition
A2: Quelle: UBA (2016), Klimawirkungsketten — visuell aus den Diagrammen abgelesen. NICHT Teil der KWRA-2021-Bewertung. Namensstand der Vulnerabilitätsanalyse 2015, auf die KWRA-2021-Klimawirkungen abgebildet. Die Exposition ist in der Quelle nur je Handlungsfeld definiert, nicht je Klimawirkung. Zuordnungsebene „Container" heißt: Der Pfeil zeigt auf das Themenfeld und gilt für alle Klimawirkungen darin.
A5: ID | B5: Cluster | C5: Handlungsfeld | D5: Klimawirkung (KWRA 2021) | E5: Hazard – klimatische Einflüsse | F5: Hazard – vorgelagerte Klimawirkungen | G5: Vulnerabilität – Sensitivitätsfaktoren | H5: Exposition – räumliches Vorkommen (Handlungsfeldebene) | I5: Zuordnungsebene | J5: Name in der Wirkungskette 2016 | K5: Status
A6: 1 | B6: Land | C6: Biologische Vielfalt | D6: Veränderung der Länge der Vegetationsperiode und Phänologie | E6: Durchschnittstemperatur | F6: Länge der Vegetationsperiode | G6: Habitat-, Biotop-, Ökosystemeigenschaften · Topographie und Landnutzung | H6: Vorkommen von Arealen, Arten und Populationen · Vorkommen von Biotopen, Habitaten und Ökosystemen | I6: Klimawirkung | J6: Phänologie; Phänologie und Verhalten; Länge der Vegetationsperiode | K6: ausgelesen
A7: 2 | B7: Land | C7: Biologische Vielfalt | D7: Ausbreitung invasiver Arten | F7: Vegetation · Tierwelt | G7: Habitat-, Biotop-, Ökosystemeigenschaften · Topographie und Landnutzung | H7: Vorkommen von Arealen, Arten und Populationen · Vorkommen von Biotopen, Habitaten und Ökosystemen | I7: Klimawirkung / V auf Container | J7: Ausbreitung invasiver Arten | K7: ausgelesen
A8: 3 | B8: Land | C8: Biologische Vielfalt | D8: Verlust an genetischer Vielfalt | F8: Beeinträchtigung der Vitalität von Pflanzen · Beeinträchtigung der Vitalität von Tieren | G8: Habitat-, Biotop-, Ökosystemeigenschaften | H8: Vorkommen von Arealen, Arten und Populationen · Vorkommen von Biotopen, Habitaten und Ökosystemen | I8: Klimawirkung | J8: Verlust an Genressourcen | K8: ausgelesen
A9: 4 | B9: Land | C9: Biologische Vielfalt | D9: Verschiebung von Arealen und Rückgang der Bestände | E9: Durchschnittstemperatur · Durchschnittlicher Niederschlag | F9: Beeinträchtigung der Vitalität von Pflanzen · Beeinträchtigung der Vitalität von Tieren · Verschiebung von Arealen · Ausbreitung invasiver Arten | G9: Habitat-, Biotop-, Ökosystemeigenschaften · Topographie und Landnutzung | H9: Vorkommen von Arealen, Arten und Populationen · Vorkommen von Biotopen, Habitaten und Ökosystemen | I9: Klimawirkung / V auf Container | J9: Verschiebung von Arealen; Rückgang der Bestände | K9: ausgelesen
A10: 5 | B10: Land | C10: Biologische Vielfalt | D10: Schäden an Küstenökosystemen | F10: Naturräumliche Schäden an Küsten | G10: Habitat-, Biotop-, Ökosystemeigenschaften · Topographie und Landnutzung | H10: Vorkommen von Arealen, Arten und Populationen · Vorkommen von Biotopen, Habitaten und Ökosystemen | I10: Klimawirkung / V auf Container | J10: Schäden an Küstenökosytemen | K10: ausgelesen
A11: 6 | B11: Land | C11: Biologische Vielfalt | D11: Schäden an Gebirgsökosystemen | E11: Durchschnittstemperatur | G11: Habitat-, Biotop-, Ökosystemeigenschaften · Topographie und Landnutzung | H11: Vorkommen von Arealen, Arten und Populationen · Vorkommen von Biotopen, Habitaten und Ökosystemen | I11: Klimawirkung / V auf Container | J11: Schäden an Gebirgsökosytemen | K11: ausgelesen
A12: 7 | B12: Land | C12: Biologische Vielfalt | D12: Schäden an wassergebundenen Habitaten und Feuchtgebieten | E12: Trockenheit | F12: Beeinträchtigung der Vitalität von Pflanzen · Beeinträchtigung der Vitalität von Tieren · Abfluss und Wasserstand von Oberflächengewässern · Grundwasserstand | G12: Habitat-, Biotop-, Ökosystemeigenschaften · Topographie und Landnutzung | H12: Vorkommen von Arealen, Arten und Populationen · Vorkommen von Biotopen, Habitaten und Ökosystemen | I12: Klimawirkung / V auf Container | J12: Schäden an wassergebundenen Habitaten und Feuchtgebieten | K12: ausgelesen
A13: 8 | B13: Land | C13: Biologische Vielfalt | D13: Schäden an Wäldern | E13: Durchschnittstemperatur | F13: Beeinträchtigung der Vitalität von Pflanzen · Beeinträchtigung der Vitalität von Tieren | G13: Habitat-, Biotop-, Ökosystemeigenschaften · Topographie und Landnutzung | H13: Vorkommen von Arealen, Arten und Populationen · Vorkommen von Biotopen, Habitaten und Ökosystemen | I13: Container | J13: Schäden an Wäldern | K13: ausgelesen
A14: 9 | B14: Land | C14: Biologische Vielfalt | D14: Ökosystemleistungen | F14: Areale, Arten und Populationen · Biotope, Habitate, Ökosysteme | G14: Habitat-, Biotop-, Ökosystemeigenschaften · Topographie und Landnutzung | H14: Vorkommen von Arealen, Arten und Populationen · Vorkommen von Biotopen, Habitaten und Ökosystemen | I14: Container | J14: Bereitstellende Dienstleistungen; Regulierende Dienstleistungen | K14: ausgelesen
A15: 10 | B15: Land | C15: Boden | D15: Bodenerosion durch Wasser | E15: Nässe · Starkregen · Trockenheit | F15: Rutschungen und Muren · Hochwasser · Sturzfluten | G15: Bodenart und Bodentyp · Topographie und Landnutzung | H15: Vorkommen von Bodenart und Bodentyp · Vorkommen von unversiegelter Fläche | I15: Klimawirkung | J15: Bodenerosion durch Wasser | K15: ausgelesen
A16: 11 | B16: Land | C16: Boden | D16: Bodenerosion durch Wind | E16: Starkwind · Trockenheit | G16: Bodenart und Bodentyp · Topographie und Landnutzung | H16: Vorkommen von Bodenart und Bodentyp · Vorkommen von unversiegelter Fläche | I16: Klimawirkung / V auf Container | J16: Bodenerosion durch Wind | K16: ausgelesen
A17: 12 | B17: Land | C17: Boden | D17: Rutschungen und Muren | E17: Starkregen · Nässe | G17: Topographie und Landnutzung · Boden- und Gesteinsschichtung | H17: Vorkommen von Bodenart und Bodentyp · Vorkommen von unversiegelter Fläche | I17: Klimawirkung / V auf Container | J17: Rutschungen und Muren | K17: ausgelesen
A18: 13 | B18: Land | C18: Boden | D18: Wassermangel im Boden | E18: Hitze · Trockenheit | F18: Grundwasserstand | G18: Bodeneigenschaften · Topographie und Landnutzung · Bewässerung | H18: Vorkommen von Bodenart und Bodentyp · Vorkommen von unversiegelter Fläche | I18: Klimawirkung / V auf Container | J18: Wassermangel im Boden | K18: ausgelesen
A19: 14 | B19: Land | C19: Boden | D19: Sickerwasser | E19: Durchschnittlicher Niederschlag · Hitze · Trockenheit · Nässe · Starkregen | G19: Bodeneigenschaften · Topographie und Landnutzung · Bewässerung | H19: Vorkommen von Bodenart und Bodentyp · Vorkommen von unversiegelter Fläche | I19: Klimawirkung / V auf Container | J19: Sickerwasser | K19: ausgelesen
A20: 15 | B20: Land | C20: Boden | D20: Vernässung | E20: Nässe · Starkregen | F20: Grundwasserstand | G20: Bodeneigenschaften · Topographie und Landnutzung · Bewässerung | H20: Vorkommen von Bodenart und Bodentyp · Vorkommen von unversiegelter Fläche | I20: Klimawirkung / V auf Container | J20: Vernässung | K20: ausgelesen
A21: 16 | B21: Land | C21: Boden | D21: Bodenbiologie: Mikrobiologische Aktivität / Biodiversität / biologische Funktionalität | F21: Bodenwärmehaushalt · Bodenwasserhaushalt · Erosion | G21: Bodeneigenschaften | H21: Vorkommen von Bodenart und Bodentyp · Vorkommen von unversiegelter Fläche | I21: Container | J21: Mikrobiologische Aktivität; Zusammensetzung von Bodenorganismen / Boden-Biodiversität; Funktionalität der Zersetzerkette | K21: ausgelesen
A22: 17 | B22: Land | C22: Boden | D22: Bodenstoffhaushalt: Organische Bodensubstanz, Stickstoff- und Phosphorhaushalt, Stoffausträge | F22: Bodenwärmehaushalt · Bodenwasserhaushalt | G22: Bodenart und Bodentyp · Bodentextur (Porenvolumen und -verteilung) | H22: Vorkommen von Bodenart und Bodentyp · Vorkommen von unversiegelter Fläche | I22: Klimawirkung | J22: Organische Bodensubstanz, Stickstoff- und Phosphorhaushalt, Stoffausträge | K22: ausgelesen
A23: 18 | B23: Land | C23: Boden | D23: Bodenfunktionen: Filter- und Pufferfunktionen | F23: Bodenwasserhaushalt · Bodenwärmehaushalt · Bodenstoffhaushalt · Bodenbiologie · Bodenstruktur · Erosion · Gravitative Massenbewegungen · Versalzung des Bodens, des Grundwassers und von Flussmündungen | G23: Bodeneigenschaften · Bodenbearbeitung · Topographie und Landnutzung | H23: Vorkommen von Bodenart und Bodentyp · Vorkommen von unversiegelter Fläche | I23: Container | J23: Filter- / Pufferfunktionen (Wasser, Schadstoffe, etc.) | K23: ausgelesen
A24: 19 | B24: Land | C24: Boden | D24: Produktionsfunktionen | F24: Bodenwasserhaushalt · Bodenwärmehaushalt · Bodenstoffhaushalt · Bodenbiologie · Bodenstruktur · Erosion · Gravitative Massenbewegungen · Versalzung des Bodens, des Grundwassers und von Flussmündungen · Nährstoffspeicherfunktionen (C, N, etc.) · Filter- / Pufferfunktionen (Wasser, Schadstoffe, etc.) | G24: Bodeneigenschaften · Bodenbearbeitung · Topographie und Landnutzung | H24: Vorkommen von Bodenart und Bodentyp · Vorkommen von unversiegelter Fläche | I24: Container + Klimawirkung | J24: Produktionsfunktionen (Standortstabilität, Bodenfruchtbarkeit) | K24: ausgelesen
A25: 20 | B25: Land | C25: Landwirtschaft | D25: Hitzestress bei und Leistung von Nutztieren | E25: Hitze | F25: Beeinträchtigung der Vitalität von Tieren · Tiergesundheit · Ertrag und Qualität der Ernteprodukte | G25: Tierart · Züchterischer Fortschritt · Möglichkeiten der Veterinärmedizin | H25: Vorkommen von landwirtschaftlicher Nutzfläche · Vorkommen von Anbauart · Vorkommen von Tierhaltung · Vorkommen von landwirtschaftlicher Infrastruktur | I25: Klimawirkung / V auf Container | J25: Hitzestress bei Tieren; Leistung von Viehhaltung, Milchwirtschaft | K25: ausgelesen
A26: 21 | B26: Land | C26: Landwirtschaft | D26: Abiotischer Stress (Pflanzen) | E26: Hitze · Früh- und Spätfröste · Wechselfrost · Hagel · Starkwind · Starkregen · Trockenheit | F26: Erosion · Bodenwasserhaushalt · Beeinträchtigung der Vitalität von Pflanzen | G26: Anbaufrucht · Dünger- und Pestizideinsatz · Züchterischer Fortschritt · Vorhandensein von Hagelschutz | H26: Vorkommen von landwirtschaftlicher Nutzfläche · Vorkommen von Anbauart · Vorkommen von Tierhaltung · Vorkommen von landwirtschaftlicher Infrastruktur | I26: Klimawirkung / V auf Container | J26: Abiotischer Stress | K26: ausgelesen
A27: 22 | B27: Land | C27: Landwirtschaft | D27: Verschiebung von Anbaugebieten | F27: Phänologie | H27: Vorkommen von landwirtschaftlicher Nutzfläche · Vorkommen von Anbauart · Vorkommen von Tierhaltung · Vorkommen von landwirtschaftlicher Infrastruktur | I27: Container | J27: Verschiebung von Anbaugebieten | K27: ausgelesen
A28: 23 | B28: Land | C28: Landwirtschaft | D28: Agrophänologische Phasen und Wachstumsperiode | F28: Phänologie | H28: Vorkommen von landwirtschaftlicher Nutzfläche · Vorkommen von Anbauart · Vorkommen von Tierhaltung · Vorkommen von landwirtschaftlicher Infrastruktur | I28: Container | J28: Agrophänologische Phasen und Wachstumsperiode | K28: ausgelesen
A29: 24 | B29: Land | C29: Landwirtschaft | D29: Stress durch Schädlinge und Krankheiten (Pflanzen) | E29: Durchschnittstemperatur · Hitze · Nässe | F29: Beeinträchtigung der Vitalität von Pflanzen | G29: Anbaufrucht · Dünger- und Pestizideinsatz · Züchterischer Fortschritt · Vorhandensein von Hagelschutz | H29: Vorkommen von landwirtschaftlicher Nutzfläche · Vorkommen von Anbauart · Vorkommen von Tierhaltung · Vorkommen von landwirtschaftlicher Infrastruktur | I29: Klimawirkung / V auf Container | J29: Stress durch Schädlinge und Krankheiten | K29: ausgelesen
A30: 25 | B30: Land | C30: Landwirtschaft | D30: Ertragsausfälle | F30: Bodenwasserhaushalt · Pflanzengesundheit · Agrophänologie · Bewässerungswasser · Bodenfunktionen | H30: Vorkommen von landwirtschaftlicher Nutzfläche · Vorkommen von Anbauart · Vorkommen von Tierhaltung · Vorkommen von landwirtschaftlicher Infrastruktur | I30: Klimawirkung | J30: Ertragsausfälle | K30: ausgelesen
A31: 26 | B31: Land | C31: Landwirtschaft | D31: Qualität der Ernteprodukte | F31: Bodenwasserhaushalt · Pflanzengesundheit · Agrophänologie · Bewässerungswasser · Bodenfunktionen | H31: Vorkommen von landwirtschaftlicher Nutzfläche · Vorkommen von Anbauart · Vorkommen von Tierhaltung · Vorkommen von landwirtschaftlicher Infrastruktur | I31: Container | J31: Qualität | K31: ausgelesen
A32: 27 | B32: Land | C32: Wald- und Forstwirtschaft | D32: Hitze- und Trockenstress | E32: Hitze · Trockenheit | F32: Bodenwasserhaushalt · Beeinträchtigung der Vitalität von Pflanzen | G32: Baumart · Baumalter / Altersstruktur | H32: Vorkommen von Waldfläche · Vorkommen von Baumarten | I32: Klimawirkung / V auf Container | J32: Hitze- und Trockenstress | K32: ausgelesen
A33: 28 | B33: Land | C33: Wald- und Forstwirtschaft | D33: Stress durch Schädlinge / Krankheiten | E33: Durchschnittstemperatur · Starkregen · Hitze · Nässe · Trockenheit · Früh- und Spätfröste | F33: Bodenwasserhaushalt · Forstphänologische Phasen und Wachstumsperiode · Beeinträchtigung der Vitalität von Pflanzen | G33: Baumart · Baumalter / Altersstruktur | H33: Vorkommen von Waldfläche · Vorkommen von Baumarten | I33: Klimawirkung / V auf Container | J33: Stress durch Schädlinge / Krankheiten | K33: ausgelesen
A34: 29 | B34: Land | C34: Wald- und Forstwirtschaft | D34: Schäden durch Windwurf | E34: Starkwind · Trockenheit | F34: Beeinträchtigung der Vitalität von Pflanzen | G34: Baumhöhe | H34: Vorkommen von Waldfläche · Vorkommen von Baumarten | I34: Klimawirkung | J34: Schäden durch Windwurf | K34: ausgelesen
A35: 30 | B35: Land | C35: Wald- und Forstwirtschaft | D35: Waldbrandrisiko | E35: Trockenheit · Hitze | G35: Baumart · Baumalter / Altersstruktur | H35: Vorkommen von Waldfläche · Vorkommen von Baumarten | I35: Klimawirkung / V auf Container | J35: Waldbrandrisiko | K35: ausgelesen
A36: 31 | B36: Land | C36: Wald- und Forstwirtschaft | D36: Nutzfunktion: Holzertrag | E36: CO2-Konzentration | F36: Bodenwasserhaushalt · Forstphänologische Phasen und Wachstumsperiode · Vitalität / Mortalitätseffekte · Baumartenzusammensetzung · Schäden an Wäldern · Areale, Arten und Populationen | G36: Waldstruktur · Standortbedingungen · Topographie und Landnutzung · Forstliche Bewirtschaftung | H36: Vorkommen von Waldfläche · Vorkommen von Baumarten | I36: Container | J36: Nutzfunktionen (Ertrag) | K36: ausgelesen
A37: 32 | B37: Land | C37: Wald- und Forstwirtschaft | D37: Nutzfunktion: Erholung | E37: CO2-Konzentration | F37: Bodenwasserhaushalt · Forstphänologische Phasen und Wachstumsperiode · Vitalität / Mortalitätseffekte · Baumartenzusammensetzung · Schäden an Wäldern · Areale, Arten und Populationen | G37: Waldstruktur · Standortbedingungen · Topographie und Landnutzung · Forstliche Bewirtschaftung | H37: Vorkommen von Waldfläche · Vorkommen von Baumarten | I37: Container | J37: Erholungsfunktionen | K37: ausgelesen
A38: 33 | B38: Wasser | C38: Fischerei | D38: Entkopplung von Nahrungsbeziehungen in der Ostsee | F38: Gewässerzustand der Meere · Gewässerzustand von Oberflächengewässern · Abfluss und Wasserstand von Oberflächengewässern · Strömungen und Gezeitendynamik · Sturmfluten · Beeinträchtigung der Vitalität von Tieren · Fischgesundheit · Areale, Arten und Populationen · Phänologie und Verhalten · Reproduktion, Wachstum und Sterblichkeit kommerziell genutzter Arten | G38: Fischbestand · Eigenschaften von Oberflächengewässern · Meerwasserqualität und Küsteneigenschaften | H38: Vorkommen von kommerziell relevanten Fischarten und -populationen · Vorkommen von Aquakulturen · Vorkommen von fischereiwirtschaftlicher Infrastruktur | I38: Container | J38: Wirkkomplex: Abiotischer Stress; Abundanz von Fischbeständen, Artenspektrum; Wachstum, Reproduktion und Sterblichkeit von Fischbeständen | K38: ausgelesen
A39: 34 | B39: Wasser | C39: Fischerei | D39: Verbreitung wärmeliebender Arten in der Nordsee | F39: Gewässerzustand der Meere · Gewässerzustand von Oberflächengewässern · Abfluss und Wasserstand von Oberflächengewässern · Strömungen und Gezeitendynamik · Sturmfluten · Beeinträchtigung der Vitalität von Tieren · Fischgesundheit · Areale, Arten und Populationen · Phänologie und Verhalten · Reproduktion, Wachstum und Sterblichkeit kommerziell genutzter Arten | G39: Fischbestand · Eigenschaften von Oberflächengewässern · Meerwasserqualität und Küsteneigenschaften | H39: Vorkommen von kommerziell relevanten Fischarten und -populationen · Vorkommen von Aquakulturen · Vorkommen von fischereiwirtschaftlicher Infrastruktur | I39: Container | J39: Wirkkomplex: Abiotischer Stress; Abundanz von Fischbeständen, Artenspektrum; Wachstum, Reproduktion und Sterblichkeit von Fischbeständen | K39: ausgelesen
A40: 35 | B40: Wasser | C40: Fischerei | D40: Verbreitung von Fischarten in Fließgewässern | F40: Gewässerzustand der Meere · Gewässerzustand von Oberflächengewässern · Abfluss und Wasserstand von Oberflächengewässern · Strömungen und Gezeitendynamik · Sturmfluten · Beeinträchtigung der Vitalität von Tieren · Fischgesundheit · Areale, Arten und Populationen · Phänologie und Verhalten · Reproduktion, Wachstum und Sterblichkeit kommerziell genutzter Arten | G40: Fischbestand · Eigenschaften von Oberflächengewässern · Meerwasserqualität und Küsteneigenschaften | H40: Vorkommen von kommerziell relevanten Fischarten und -populationen · Vorkommen von Aquakulturen · Vorkommen von fischereiwirtschaftlicher Infrastruktur | I40: Container | J40: Wirkkomplex: Abiotischer Stress; Abundanz von Fischbeständen, Artenspektrum; Wachstum, Reproduktion und Sterblichkeit von Fischbeständen | K40: ausgelesen
A41: 36 | B41: Wasser | C41: Fischerei | D41: Stress durch Schädlinge / Krankheiten | F41: Gewässerzustand der Meere · Gewässerzustand von Oberflächengewässern · Abfluss und Wasserstand von Oberflächengewässern · Strömungen und Gezeitendynamik · Sturmfluten · Beeinträchtigung der Vitalität von Tieren | G41: Fischart · Infektionsanfälligkeit | H41: Vorkommen von kommerziell relevanten Fischarten und -populationen · Vorkommen von Aquakulturen · Vorkommen von fischereiwirtschaftlicher Infrastruktur | I41: Container | J41: Stress durch Schädlinge / Krankheiten | K41: ausgelesen
A42: 37 | B42: Wasser | C42: Fischerei | D42: Schäden an Aquakulturen | F42: Abfluss und Wasserstand von Oberflächengewässern · Wasserstand der Meere | G42: Aquakultursystem (Offene Systeme, Geschlossene Systeme, etc.) | H42: Vorkommen von kommerziell relevanten Fischarten und -populationen · Vorkommen von Aquakulturen · Vorkommen von fischereiwirtschaftlicher Infrastruktur | I42: Klimawirkung | J42: Schäden an Aquakulturen | K42: ausgelesen
...

Sheet Faktoren-Ranking
A1: Welcher Faktor betrifft wie viele der 102 Klimawirkungen?
A2: Abgeleitet aus dem Blatt „Wirkungsmechanismen“ (Quelle: UBA 2016, Klimawirkungsketten).
A4: Hazard – klimatische Einflüsse | B4: Anzahl | D4: Hazard – vorgelagerte Klimawirkungen | E4: Anzahl | G4: Vulnerabilität – Sensitivitätsfaktoren | H4: Anzahl
A5: Hitze | B5: 27 | D5: Sturmfluten | E5: 15 | G5: Topographie und Landnutzung | H5: 21
A6: Starkregen | B6: 22 | D6: Bodenwasserhaushalt | E6: 11 | G6: Bauliche, organisatorische und finanzielle Vorsorge der Unternehmen | H6: 12
A7: Starkwind | B7: 22 | D7: Abfluss und Wasserstand von Oberflächengewässern | E7: 10 | G7: Größe des Unternehmens / Anzahl und Größe der Standorte | H7: 10
A8: Durchschnittstemperatur | B8: 19 | D8: Strömungen und Gezeitendynamik | E8: 10 | G8: Habitat-, Biotop-, Ökosystemeigenschaften | H8: 9
A9: Trockenheit | B9: 15 | D9: Beeinträchtigung der Vitalität von Pflanzen | E9: 9 | G9: Bodeneigenschaften | H9: 6
A10: Kälte / Frost | B10: 13 | D10: Beeinträchtigung der Vitalität von Tieren | E10: 9 | G10: Individuelles Gefahrenbewusstsein | H10: 6
A11: Sonnenscheindauer | B11: 11 | D11: Meeresspiegelhöhe | E11: 9 | G11: Eigenschaften des Meeres | H11: 5
A12: Nässe | B12: 10 | D12: Gravitative Massenbewegungen | E12: 8 | G12: Monitoring von Gesundheitsgefahren und Frühwarnsysteme | H12: 5
A13: Durchschnittlicher Niederschlag | B13: 8 | D13: Gewässerzustand von Oberflächengewässern | E13: 8 | G13: Bauliche und organisatorische Vorsorge an Infrastrukturen | H13: 4
A14: Hagel | B14: 7 | D14: Grundwasserstand | E14: 7 | G14: Zustand von Infrastrukturen | H14: 4
A15: Luftfeuchtigkeit | B15: 7 | D15: Hochwasser | E15: 7 | G15: Verwendete Baumaterialien / Gestaltung | H15: 4
A16: Globales Klima | B16: 5 | D16: Areale, Arten und Populationen | E16: 6 | G16: Begrünung von Infrastrukturen | H16: 4
... A29: UV-Strahlung | B29: 1 | D29: Wasserstand der Meere | E29: 3 | G29: Flussgebietseigenschaften | H29: 3

Sheet Wirkbeziehungen
A1: Wirkbeziehungen zwischen den Klimawirkungen
A2: Die KWRA nennt 257 Querverbindungen, veröffentlicht die Einzelkanten aber in keinem der sechs Teilberichte als Liste. Abbildung 8 in Teilbericht 6 ist ein Chord-Diagramm auf Handlungsfeldebene, aus dem sich keine exakten Kantenzahlen ablesen lassen. Dieses Blatt enthält deshalb nur, was belegt ist.
A5: 1. Kennzahlen (Teilbericht 6, Kapitel 3.4)
A6: Querverbindungen insgesamt | B6: 257
A7: Durchschnitt je Klimawirkung | B7: rund 2,5 ein- oder ausgehende Beziehungen
A8: Klimawirkungen mit ausgehenden Beziehungen | B8: 71 von 102
A9: Klimawirkungen mit eingehenden Beziehungen | B9: 62 von 102
A10: Handlungsfeld mit den meisten ausgehenden Beziehungen | B10: Wasserhaushalt, Wasserwirtschaft
A11: Handlungsfeld mit den meisten eingehenden Beziehungen | B11: Tourismuswirtschaft
A12: Nur ausgehende Beziehungen | B12: Küsten- und Meeresschutz
A13: Nur eingehende Beziehungen | B13: Tourismuswirtschaft
A15: 2. Querverbindungen zwischen den Systembereichen (Teilbericht 6, Tabelle 28)
A16: Rein vorgelagerte Klimawirkungen sind in dieser Matrix nicht enthalten. Die Diagonale zählt Wirkbeziehungen innerhalb desselben Systembereichs; die Summenspalte nur die Beziehungen zu den vier anderen Systembereichen.
A17: von ↓ / zu → | B17: Natürliche Systeme und Ressourcen | C17: Naturnutzende Wirtschaftssysteme | D17: Infrastrukturen und Gebäude | E17: Naturferne Wirtschaftssysteme | F17: Menschen und soziale Systeme | G17: Summe ausgehend
A18: Natürliche Systeme und Ressourcen | B18: 24 | C18: 50 | D18: 13 | E18: 9 | F18: 8 | G18: 80
A19: Naturnutzende Wirtschaftssysteme | B19: 6 | C19: 44 | D19: 13 | E19: 8 | F19: 8 | G19: 35
A20: Infrastrukturen und Gebäude | B20: 3 | C20: 3 | D20: 26 | E20: 13 | F20: 11 | G20: 30
A21: Naturferne Wirtschaftssysteme | B21: 0 | C21: 0 | D21: 0 | E21: 5 | F21: 0 | G21: 0
A22: Menschen und soziale Systeme | B22: 0 | C22: 4 | D22: 1 | E22: 7 | F22: 6 | G22: 12
A24: 3. Im Fließtext ausdrücklich benannte Einzelbeziehungen (Auszug, nicht vollständig)
A25: Quelle (wirkt auf) | B25: Ziel (wird beeinflusst) | C25: Ebene | D25: Beleg
A26: Hochwasser | B26: zahlreiche Klimawirkungen in mehreren Handlungsfeldern | C26: Klimawirkung | D26: TB6 Kap. 3.4: zentrale Klimawirkung, wirkt sich auf die meisten anderen aus
A27: Gewässertemperatur und Eisbedeckung und biologische Wasserqualität | B27: Potenziell schädliche Mikroorganismen und Algen | C27: Klimawirkung | D27: TB6 Kap. 3.4: fördert deren Entwicklung
A28: Stadtklima / Wärmeinseln | B28: Hitzebelastung | C28: Klimawirkung | D28: TB6 Kap. 3.4: zunehmender urbaner Wärmeinseleffekt erhöht die Hitzebelastung
A29: Veränderung der Länge der Vegetationsperiode und Phänologie | B29: Allergische Reaktionen durch Aeroallergene pflanzlicher Herkunft | C29: Klimawirkung | D29: TB6 Kap. 3.4: verlängerte Vegetationsperiode verstärkt Pollenreaktionen
A30: Hochwasser | B30: Verletzungen und Todesfälle infolge von Extremereignissen | C30: Klimawirkung | D30: TB6 Kap. 3.4
A31: Sturzfluten (Versagen von Entwässerungseinrichtungen und Überflutungsschutzsystemen) | B31: Verletzungen und Todesfälle infolge von Extremereignissen | C31: Klimawirkung | D31: TB6 Kap. 3.4
A32: Niedrigwasser | B32: Beeinträchtigung des Warenverkehrs über Wasserstraßen (Inland) | C32: Klimawirkung | D32: TB6 Kap. 3.4: niedrigwasserbedingte Einschränkungen im Warentransport
A33: Hochwasser | B33: Schäden / Hindernisse bei Straßen und Schienenwegen (Hochwasser) | C33: Klimawirkung | D33: TB6 Kap. 3.4: Beeinträchtigung der Verkehrswege
A34: Boden (Handlungsfeld) | B34: Grundwasserstand und Grundwasserqualität | C34: gemischt | D34: TB6 Kap. 3.4: viele Klimawirkungen des Bodens wirken hierauf ein
A35: Boden und Biologische Vielfalt (Handlungsfelder) | B35: Ertragsausfälle | C35: gemischt | D35: TB6 Kap. 3.4: landwirtschaftliche Ertragsausfälle werden von vielen Klimawirkungen dieser Handlungsfelder beeinflusst
A36: Boden und Biologische Vielfalt (Handlungsfelder) | B36: Qualität der Ernteprodukte | C36: gemischt | D36: TB6 Kap. 3.4
... A45: Wasserhaushalt, Wasserwirtschaft (Handlungsfeld) | B45: Tourismuswirtschaft (Handlungsfeld) | C45: Handlungsfeld | D45: TB6 Kap. 3.4
A47: Für das Produkt: Die Spalte „Netzrolle“ im Blatt „Klimawirkungen“ markiert die 25 Klimawirkungen, die Teilbericht 6 ausdrücklich als starke Sender oder Empfänger benennt. Eine vollständige Kantenliste müsste eigenständig modelliert und als solche gekennzeichnet werden – sie ist keine KWRA-Angabe.

Sheet Lesehinweise
A1: KWRA 2021 – 102 Klimawirkungen: Lesehinweise
A2: Vollständig aufbereitet aus allen sechs Teilberichten der Klimawirkungs- und Risikoanalyse 2021 (Umweltbundesamt).
A4: Belegstatus
A5: Vollständig | B5: Alle Spalten sind aus den Teilberichten belegt. Es gibt keine geschätzten oder abgeleiteten Werte mehr.
A6: Leere Zellen sind korrekt | B6: Die Anpassungsspalten (Wirksamkeit, Restrisiko) sind nur für die 33 Klimawirkungen befüllt, für die die KWRA die Anpassungskapazität analysiert hat. Für die übrigen 69 existieren diese Bewertungen nicht. Spezifizierung und Indikatoren gibt es nur für intensiv bearbeitete Klimawirkungen.
A8: Kontrollsummen – alle stimmen mit der KWRA überein
A9: 102 Klimawirkungen | B9: 32 Land + 26 Wasser + 19 Infrastruktur + 17 Wirtschaft + 8 Gesundheit
A10: 13 Handlungsfelder | B10: eigenes Blatt mit den Bewertungen auf Handlungsfeldebene
A11: 31 sehr dringend | B11: Teilbericht 6, Tabelle 25
A12: 23 dringend | B12: Teilbericht 6, Tabelle 26
A13: 33 mit Anpassungskapazität | B13: Teilbericht 6, Tabelle 22
A14: 37 intensiv bearbeitet | B14: Teilberichte 2–5, Übersichtstabellen je Handlungsfeld — entspricht 35 namentlich benannten Klimawirkungen, weil „Schäden an Gebäuden“ und „Einschränkungen touristischer Angebote“ hier in je zwei Spezifizierungszeilen stehen
A15: 9 rein vorgelagert | B15: in Teilbericht 6, Tabelle 1 mit „*“ gekennzeichnet
A16: 2 Chancen | B16: Bedarf an Heizenergie; Wettbewerbsvorteil in innovativen Umwelttechnologien
A18: Die vier Blöcke im Blatt „Klimawirkungen“
A19: Stamm (A–D) | B19: Cluster, Handlungsfeld, Klimawirkung. Die ID ist der stabile Schlüssel.
A20: A. Fachliche Zerlegung (E–M) | B20: Bearbeitungstiefe, Spezifizierung, integrierte Klimawirkungen, Faktoren, Indikatoren, Typ, Vorgelagert-Kennzeichen, Systembereich.
A21: B. Risiko ohne Anpassung (N–U) | B21: Dreistufig (gering/mittel/hoch) für fünf Kombinationen aus Zeitscheibe und Fall, dazu Gewissheit und Anpassungsdauer.
A22: C. Anpassung (V–AJ) | B22: Wirksamkeit der Maßnahmen, verbleibendes Restrisiko, Handlungserfordernis und Grenzen der Anpassung. Fünfstufige Skala.
A24: Wirksamkeit ist nicht Restrisiko
A25: Wirksamkeit | B25: Wie stark die Maßnahmen das Risiko senken können. Quelle: Teilbericht 6, Tabelle 22.
A26: Restrisiko | B26: Welches Risiko nach der Anpassung verbleibt. Quelle: Teilberichte 2–5, Tabellen „Klimarisiken mit Anpassung im Handlungsfeld …“. Das ist die Größe, die für Anpassungsentscheidungen zählt.
A27: APA III | B27: Aktionsplan Anpassung III – die bereits beschlossenen Maßnahmen des Bundes. „Weiterreichend“ meint darüber hinausgehende Maßnahmen.
A29: Worauf beim Einbauen zu achten ist
A30: Namensgleichheit | B30: „Stress durch Schädlinge / Krankheiten“ existiert wortgleich in Wald- und Forstwirtschaft (ID 28) und in Fischerei (ID 36) – mit unterschiedlicher Bearbeitungstiefe, unterschiedlichen Bewertungen und unterschiedlichem Handlungserfordernis. Immer über die ID verknüpfen, nie über den Namen.
A31: Rein vorgelagerte Klimawirkungen | B31: Neun physische Veränderungen ohne Anpassungsoption, etwa der Meeresspiegelanstieg. Sie wurden nur ohne Anpassung bewertet und sollten nicht wie handlungsleitende Risiken dargestellt werden.
A32: Grenzen der Anpassung | B32: Vier Klimawirkungen haben ein mittleres bis hohes Risiko, aber keine Anpassungsoption: Bodenbiologie, Bodenfunktionen, Veränderung der Vegetationsperiode und Schäden an Gebirgsökosystemen. Sie sind keiner Dringlichkeitsstufe zugeordnet.
A33: Abweichende Namen in den Teilberichten | B33: Einzelne Klimawirkungen heißen in den Teilberichten 2–5 leicht anders als in Teilbericht 6 (zum Beispiel „Schäden in Wäldern“ statt „Schäden an Wäldern“, „Nutzfunktion (Holzertrag)“ statt „Nutzfunktion: Holzertrag“). Diese Tabelle folgt durchgängig der Schreibweise aus Teilbericht 6, Tabelle 1.
A34: Unstimmigkeit im Bericht | B34: Teilbericht 6 nennt in Kapitel 6.1 auch „Biologische Vielfalt“ als Handlungsfeld mit rein vorgelagerten Klimawirkungen. In Tabelle 1 ist dort jedoch keine mit „*“ markiert. Diese Tabelle folgt der Markierung in Tabelle 1.
A36: Querschnittsfelder – bewusst nicht enthalten
A37: Raumordnung, Bevölkerungsschutz, Finanzwirtschaft | B37: Keine Handlungsfelder und ohne eigene Klimawirkungen. Sie liefern Anpassungskapazität in die 13 Handlungsfelder hinein.
A39: Was noch fehlt
A40: 257 Wirkbeziehungen | B40: Die KWRA nennt 257 Querverbindungen, veröffentlicht die Einzelkanten aber in keinem Teilbericht als Liste. Das Blatt „Wirkbeziehungen“ enthält alles, was belegt ist: die Kennzahlen, die exakte Matrix der fünf Systembereiche und die im Fließtext benannten Einzelbeziehungen. Eine vollständige Kantenliste müsste eigenständig modelliert werden.
A41: Räumliche Ebene | B41: Bewertungen je Klimaraumtyp (7 Typen) und die Hotspot-Karten.
A42: Anpassungsdimensionen | B42: Teilberichte 2–5 enthalten je Klimawirkung die Beiträge in den sechs Anpassungsdimensionen auf einer Skala von 1 bis 5.
A44: Quellen
B45: Teilbericht 2: Cluster Land (Climate Change 21/2021)
B46: Teilbericht 3: Cluster Wasser (Climate Change 22/2021)
B47: Teilbericht 4: Cluster Infrastruktur (Climate Change 23/2021)
B48: Teilbericht 5: Cluster Wirtschaft und Gesundheit (Climate Change 24/2021)
...

Sheet Codelisten
A1: Zulässige Werte (KWRA-Skalen)
A3: Klimarisiko ohne Anpassung (Klimawirkungsebene)
B4: gering
B5: mittel
B6: hoch
A8: Wirksamkeit, Restrisiko, Handlungsfeldebene (5-stufig)
B9: gering
B10: gering-mittel
B11: mittel
B12: mittel-hoch
B13: hoch
A15: Gewissheit
B16: sehr gering
B17: gering
B18: mittel
B19: hoch
A21: Anpassungsdauer
B22: < 10
B23: 10-50
B24: > 50
B25: keine Reaktion möglich
A27: Bearbeitungstiefe
B28: intensiv (37 Zeilen / 35 benannte Klimawirkungen, mit Indikatoren und quantitativen Daten)
B29: extensiv (65 Zeilen, qualitativ)
A31: Handlungserfordernis
B32: sehr dringend (31)
B33: dringend (23)
B34: nicht als (sehr) dringend ausgewiesen (44)
B35: nicht zuordenbar, keine Anpassungsoption (4)
A37: Systembereiche (5)
B38: Natürliche Systeme und Ressourcen (N)
B39: Naturnutzende Wirtschaftssysteme (Nn)
B40: Infrastrukturen und Gebäude (I&G)
B41: Naturferne Wirtschaftssysteme (Nf)
B42: Menschen und soziale Systeme (M)
A44: Schutzgüter (4)
B45: Mensch
B46: Volkswirtschaft
B47: Umwelt
B48: kulturelles Erbe
...

Sheet Auswertung
A1: Auswertung (Formeln, aktualisieren sich mit dem Datenblatt)
A3: Klimawirkungen je Cluster
A4: Cluster | B4: Anzahl | C4: sehr dringend | D4: dringend
A5: Land | B5: =COUNTIF(Klimawirkungen!$B$3:$B$104,$A5) -> 32 | C5: =COUNTIFS(Klimawirkungen!$B$3:$B$104,$A5,Klimawirkungen!$AG$3:$AG$104,"sehr dringend") -> 13 | D5: =COUNTIFS(Klimawirkungen!$B$3:$B$104,$A5,Klimawirkungen!$AG$3:$AG$104,"dringend") -> 7
A6: Wasser | B6: =COUNTIF(Klimawirkungen!$B$3:$B$104,$A6) -> 26 | C6: =COUNTIFS(Klimawirkungen!$B$3:$B$104,$A6,Klimawirkungen!$AG$3:$AG$104,"sehr dringend") -> 9 | D6: =COUNTIFS(Klimawirkungen!$B$3:$B$104,$A6,Klimawirkungen!$AG$3:$AG$104,"dringend") -> 5
